#include <stdexcept>

void lanzaException() {
    throw std::runtime_error("Error en la funci√≥n lanzaException");
}


int main() {
    lanzaException();

    return 0;
}
